pydev debugger: process 7298 is connecting

Iniciando convers√£o dos audios em espectogramas e log_energy
Traceback (most recent call last):
  File "/snap/pycharm-community/207/plugins/python-ce/helpers/pydev/_pydevd_bundle/pydevd_comm.py", line 290, in _on_run
    r = self.sock.recv(1024)
OSError: [Errno 9] Bad file descriptor
[Parallel(n_jobs=4)]: Using backend MultiprocessingBackend with 4 concurrent workers.
[Parallel(n_jobs=4)]: Done   0 out of   0 | elapsed:    0.0s finished
[]
Error in atexit._run_exitfuncs:
Traceback (most recent call last):
  File "/snap/pycharm-community/207/plugins/python-ce/helpers/pydev/pydevd.py", line 1785, in stoptrace
    debugger.exiting()
  File "/snap/pycharm-community/207/plugins/python-ce/helpers/pydev/pydevd.py", line 1471, in exiting
    sys.stdout.flush()
ValueError: I/O operation on closed file.
